2025-10-17 11:39:47,045 - __main__ - INFO - Starting Enhanced Instagram Downloader Bot with Django integration...
2025-10-17 11:39:47,475 - httpx - INFO - HTTP Request: POST https://api.telegram.org/bot8276877025:AAFFPx5w397Zris6iSzFCe4cs6yrcwnnx0E/getMe "HTTP/1.1 200 OK"
2025-10-17 11:39:47,581 - httpx - INFO - HTTP Request: POST https://api.telegram.org/bot8276877025:AAFFPx5w397Zris6iSzFCe4cs6yrcwnnx0E/deleteWebhook "HTTP/1.1 200 OK"
2025-10-17 11:39:47,585 - telegram.ext.Application - INFO - Application started
2025-10-17 11:39:53,010 - httpx - INFO - HTTP Request: POST https://api.telegram.org/bot8276877025:AAFFPx5w397Zris6iSzFCe4cs6yrcwnnx0E/getUpdates "HTTP/1.1 200 OK"
2025-10-17 11:39:53,014 - telegram.ext.Application - ERROR - No error handlers are registered, logging exception.
Traceback (most recent call last):
  File "/home/salohiddin/downlaoderf/venv/lib/python3.13/site-packages/telegram/ext/_application.py", line 1335, in process_update
    await coroutine
  File "/home/salohiddin/downlaoderf/venv/lib/python3.13/site-packages/telegram/ext/_handlers/basehandler.py", line 157, in handle_update
    return await self.callback(update, context)
           ^^^^^^^^^^^^^^^^^^^^^^^^^^^^^^^^^^^^
  File "/home/salohiddin/downlaoderf/instagram-downloader/enhanced_telegram_bot.py", line 54, in start_command
    telegram_user = TelegramUser.objects.filter(telegram_id=user_id).first()
  File "/home/salohiddin/downlaoderf/venv/lib/python3.13/site-packages/django/db/models/query.py", line 1104, in first
    for obj in queryset[:1]:
               ~~~~~~~~^^^^
  File "/home/salohiddin/downlaoderf/venv/lib/python3.13/site-packages/django/db/models/query.py", line 384, in __iter__
    self._fetch_all()
    ~~~~~~~~~~~~~~~^^
  File "/home/salohiddin/downlaoderf/venv/lib/python3.13/site-packages/django/db/models/query.py", line 1945, in _fetch_all
    self._result_cache = list(self._iterable_class(self))
                         ~~~~^^^^^^^^^^^^^^^^^^^^^^^^^^^^
  File "/home/salohiddin/downlaoderf/venv/lib/python3.13/site-packages/django/db/models/query.py", line 91, in __iter__
    results = compiler.execute_sql(
        chunked_fetch=self.chunked_fetch, chunk_size=self.chunk_size
    )
  File "/home/salohiddin/downlaoderf/venv/lib/python3.13/site-packages/django/db/models/sql/compiler.py", line 1621, in execute_sql
    cursor = self.connection.cursor()
  File "/home/salohiddin/downlaoderf/venv/lib/python3.13/site-packages/django/utils/asyncio.py", line 24, in inner
    raise SynchronousOnlyOperation(message)
django.core.exceptions.SynchronousOnlyOperation: You cannot call this from an async context - use a thread or sync_to_async.
2025-10-17 11:39:53,748 - httpx - INFO - HTTP Request: POST https://api.telegram.org/bot8276877025:AAFFPx5w397Zris6iSzFCe4cs6yrcwnnx0E/getUpdates "HTTP/1.1 200 OK"
2025-10-17 11:39:53,750 - telegram.ext.Application - ERROR - No error handlers are registered, logging exception.
Traceback (most recent call last):
  File "/home/salohiddin/downlaoderf/venv/lib/python3.13/site-packages/telegram/ext/_application.py", line 1335, in process_update
    await coroutine
  File "/home/salohiddin/downlaoderf/venv/lib/python3.13/site-packages/telegram/ext/_handlers/basehandler.py", line 157, in handle_update
    return await self.callback(update, context)
           ^^^^^^^^^^^^^^^^^^^^^^^^^^^^^^^^^^^^
  File "/home/salohiddin/downlaoderf/instagram-downloader/enhanced_telegram_bot.py", line 54, in start_command
    telegram_user = TelegramUser.objects.filter(telegram_id=user_id).first()
  File "/home/salohiddin/downlaoderf/venv/lib/python3.13/site-packages/django/db/models/query.py", line 1104, in first
    for obj in queryset[:1]:
               ~~~~~~~~^^^^
  File "/home/salohiddin/downlaoderf/venv/lib/python3.13/site-packages/django/db/models/query.py", line 384, in __iter__
    self._fetch_all()
    ~~~~~~~~~~~~~~~^^
  File "/home/salohiddin/downlaoderf/venv/lib/python3.13/site-packages/django/db/models/query.py", line 1945, in _fetch_all
    self._result_cache = list(self._iterable_class(self))
                         ~~~~^^^^^^^^^^^^^^^^^^^^^^^^^^^^
  File "/home/salohiddin/downlaoderf/venv/lib/python3.13/site-packages/django/db/models/query.py", line 91, in __iter__
    results = compiler.execute_sql(
        chunked_fetch=self.chunked_fetch, chunk_size=self.chunk_size
    )
  File "/home/salohiddin/downlaoderf/venv/lib/python3.13/site-packages/django/db/models/sql/compiler.py", line 1621, in execute_sql
    cursor = self.connection.cursor()
  File "/home/salohiddin/downlaoderf/venv/lib/python3.13/site-packages/django/utils/asyncio.py", line 24, in inner
    raise SynchronousOnlyOperation(message)
django.core.exceptions.SynchronousOnlyOperation: You cannot call this from an async context - use a thread or sync_to_async.
2025-10-17 11:39:53,943 - httpx - INFO - HTTP Request: POST https://api.telegram.org/bot8276877025:AAFFPx5w397Zris6iSzFCe4cs6yrcwnnx0E/getUpdates "HTTP/1.1 200 OK"
2025-10-17 11:39:53,944 - telegram.ext.Application - ERROR - No error handlers are registered, logging exception.
Traceback (most recent call last):
  File "/home/salohiddin/downlaoderf/venv/lib/python3.13/site-packages/telegram/ext/_application.py", line 1335, in process_update
    await coroutine
  File "/home/salohiddin/downlaoderf/venv/lib/python3.13/site-packages/telegram/ext/_handlers/basehandler.py", line 157, in handle_update
    return await self.callback(update, context)
           ^^^^^^^^^^^^^^^^^^^^^^^^^^^^^^^^^^^^
  File "/home/salohiddin/downlaoderf/instagram-downloader/enhanced_telegram_bot.py", line 54, in start_command
    telegram_user = TelegramUser.objects.filter(telegram_id=user_id).first()
  File "/home/salohiddin/downlaoderf/venv/lib/python3.13/site-packages/django/db/models/query.py", line 1104, in first
    for obj in queryset[:1]:
               ~~~~~~~~^^^^
  File "/home/salohiddin/downlaoderf/venv/lib/python3.13/site-packages/django/db/models/query.py", line 384, in __iter__
    self._fetch_all()
    ~~~~~~~~~~~~~~~^^
  File "/home/salohiddin/downlaoderf/venv/lib/python3.13/site-packages/django/db/models/query.py", line 1945, in _fetch_all
    self._result_cache = list(self._iterable_class(self))
                         ~~~~^^^^^^^^^^^^^^^^^^^^^^^^^^^^
  File "/home/salohiddin/downlaoderf/venv/lib/python3.13/site-packages/django/db/models/query.py", line 91, in __iter__
    results = compiler.execute_sql(
        chunked_fetch=self.chunked_fetch, chunk_size=self.chunk_size
    )
  File "/home/salohiddin/downlaoderf/venv/lib/python3.13/site-packages/django/db/models/sql/compiler.py", line 1621, in execute_sql
    cursor = self.connection.cursor()
  File "/home/salohiddin/downlaoderf/venv/lib/python3.13/site-packages/django/utils/asyncio.py", line 24, in inner
    raise SynchronousOnlyOperation(message)
django.core.exceptions.SynchronousOnlyOperation: You cannot call this from an async context - use a thread or sync_to_async.
2025-10-17 11:39:54,046 - httpx - INFO - HTTP Request: POST https://api.telegram.org/bot8276877025:AAFFPx5w397Zris6iSzFCe4cs6yrcwnnx0E/getUpdates "HTTP/1.1 200 OK"
2025-10-17 11:39:54,047 - telegram.ext.Application - ERROR - No error handlers are registered, logging exception.
Traceback (most recent call last):
  File "/home/salohiddin/downlaoderf/venv/lib/python3.13/site-packages/telegram/ext/_application.py", line 1335, in process_update
    await coroutine
  File "/home/salohiddin/downlaoderf/venv/lib/python3.13/site-packages/telegram/ext/_handlers/basehandler.py", line 157, in handle_update
    return await self.callback(update, context)
           ^^^^^^^^^^^^^^^^^^^^^^^^^^^^^^^^^^^^
  File "/home/salohiddin/downlaoderf/instagram-downloader/enhanced_telegram_bot.py", line 54, in start_command
    telegram_user = TelegramUser.objects.filter(telegram_id=user_id).first()
  File "/home/salohiddin/downlaoderf/venv/lib/python3.13/site-packages/django/db/models/query.py", line 1104, in first
    for obj in queryset[:1]:
               ~~~~~~~~^^^^
  File "/home/salohiddin/downlaoderf/venv/lib/python3.13/site-packages/django/db/models/query.py", line 384, in __iter__
    self._fetch_all()
    ~~~~~~~~~~~~~~~^^
  File "/home/salohiddin/downlaoderf/venv/lib/python3.13/site-packages/django/db/models/query.py", line 1945, in _fetch_all
    self._result_cache = list(self._iterable_class(self))
                         ~~~~^^^^^^^^^^^^^^^^^^^^^^^^^^^^
  File "/home/salohiddin/downlaoderf/venv/lib/python3.13/site-packages/django/db/models/query.py", line 91, in __iter__
    results = compiler.execute_sql(
        chunked_fetch=self.chunked_fetch, chunk_size=self.chunk_size
    )
  File "/home/salohiddin/downlaoderf/venv/lib/python3.13/site-packages/django/db/models/sql/compiler.py", line 1621, in execute_sql
    cursor = self.connection.cursor()
  File "/home/salohiddin/downlaoderf/venv/lib/python3.13/site-packages/django/utils/asyncio.py", line 24, in inner
    raise SynchronousOnlyOperation(message)
django.core.exceptions.SynchronousOnlyOperation: You cannot call this from an async context - use a thread or sync_to_async.
2025-10-17 11:39:54,192 - httpx - INFO - HTTP Request: POST https://api.telegram.org/bot8276877025:AAFFPx5w397Zris6iSzFCe4cs6yrcwnnx0E/getUpdates "HTTP/1.1 200 OK"
2025-10-17 11:39:54,194 - telegram.ext.Application - ERROR - No error handlers are registered, logging exception.
Traceback (most recent call last):
  File "/home/salohiddin/downlaoderf/venv/lib/python3.13/site-packages/telegram/ext/_application.py", line 1335, in process_update
    await coroutine
  File "/home/salohiddin/downlaoderf/venv/lib/python3.13/site-packages/telegram/ext/_handlers/basehandler.py", line 157, in handle_update
    return await self.callback(update, context)
           ^^^^^^^^^^^^^^^^^^^^^^^^^^^^^^^^^^^^
  File "/home/salohiddin/downlaoderf/instagram-downloader/enhanced_telegram_bot.py", line 54, in start_command
    telegram_user = TelegramUser.objects.filter(telegram_id=user_id).first()
  File "/home/salohiddin/downlaoderf/venv/lib/python3.13/site-packages/django/db/models/query.py", line 1104, in first
    for obj in queryset[:1]:
               ~~~~~~~~^^^^
  File "/home/salohiddin/downlaoderf/venv/lib/python3.13/site-packages/django/db/models/query.py", line 384, in __iter__
    self._fetch_all()
    ~~~~~~~~~~~~~~~^^
  File "/home/salohiddin/downlaoderf/venv/lib/python3.13/site-packages/django/db/models/query.py", line 1945, in _fetch_all
    self._result_cache = list(self._iterable_class(self))
                         ~~~~^^^^^^^^^^^^^^^^^^^^^^^^^^^^
  File "/home/salohiddin/downlaoderf/venv/lib/python3.13/site-packages/django/db/models/query.py", line 91, in __iter__
    results = compiler.execute_sql(
        chunked_fetch=self.chunked_fetch, chunk_size=self.chunk_size
    )
  File "/home/salohiddin/downlaoderf/venv/lib/python3.13/site-packages/django/db/models/sql/compiler.py", line 1621, in execute_sql
    cursor = self.connection.cursor()
  File "/home/salohiddin/downlaoderf/venv/lib/python3.13/site-packages/django/utils/asyncio.py", line 24, in inner
    raise SynchronousOnlyOperation(message)
django.core.exceptions.SynchronousOnlyOperation: You cannot call this from an async context - use a thread or sync_to_async.
2025-10-17 11:40:00,931 - httpx - INFO - HTTP Request: POST https://api.telegram.org/bot8276877025:AAFFPx5w397Zris6iSzFCe4cs6yrcwnnx0E/getUpdates "HTTP/1.1 200 OK"
2025-10-17 11:40:00,932 - telegram.ext.Application - ERROR - No error handlers are registered, logging exception.
Traceback (most recent call last):
  File "/home/salohiddin/downlaoderf/venv/lib/python3.13/site-packages/telegram/ext/_application.py", line 1335, in process_update
    await coroutine
  File "/home/salohiddin/downlaoderf/venv/lib/python3.13/site-packages/telegram/ext/_handlers/basehandler.py", line 157, in handle_update
    return await self.callback(update, context)
           ^^^^^^^^^^^^^^^^^^^^^^^^^^^^^^^^^^^^
  File "/home/salohiddin/downlaoderf/instagram-downloader/enhanced_telegram_bot.py", line 54, in start_command
    telegram_user = TelegramUser.objects.filter(telegram_id=user_id).first()
  File "/home/salohiddin/downlaoderf/venv/lib/python3.13/site-packages/django/db/models/query.py", line 1104, in first
    for obj in queryset[:1]:
               ~~~~~~~~^^^^
  File "/home/salohiddin/downlaoderf/venv/lib/python3.13/site-packages/django/db/models/query.py", line 384, in __iter__
    self._fetch_all()
    ~~~~~~~~~~~~~~~^^
  File "/home/salohiddin/downlaoderf/venv/lib/python3.13/site-packages/django/db/models/query.py", line 1945, in _fetch_all
    self._result_cache = list(self._iterable_class(self))
                         ~~~~^^^^^^^^^^^^^^^^^^^^^^^^^^^^
  File "/home/salohiddin/downlaoderf/venv/lib/python3.13/site-packages/django/db/models/query.py", line 91, in __iter__
    results = compiler.execute_sql(
        chunked_fetch=self.chunked_fetch, chunk_size=self.chunk_size
    )
  File "/home/salohiddin/downlaoderf/venv/lib/python3.13/site-packages/django/db/models/sql/compiler.py", line 1621, in execute_sql
    cursor = self.connection.cursor()
  File "/home/salohiddin/downlaoderf/venv/lib/python3.13/site-packages/django/utils/asyncio.py", line 24, in inner
    raise SynchronousOnlyOperation(message)
django.core.exceptions.SynchronousOnlyOperation: You cannot call this from an async context - use a thread or sync_to_async.
2025-10-17 11:40:01,189 - httpx - INFO - HTTP Request: POST https://api.telegram.org/bot8276877025:AAFFPx5w397Zris6iSzFCe4cs6yrcwnnx0E/getUpdates "HTTP/1.1 200 OK"
2025-10-17 11:40:01,190 - telegram.ext.Application - ERROR - No error handlers are registered, logging exception.
Traceback (most recent call last):
  File "/home/salohiddin/downlaoderf/venv/lib/python3.13/site-packages/telegram/ext/_application.py", line 1335, in process_update
    await coroutine
  File "/home/salohiddin/downlaoderf/venv/lib/python3.13/site-packages/telegram/ext/_handlers/basehandler.py", line 157, in handle_update
    return await self.callback(update, context)
           ^^^^^^^^^^^^^^^^^^^^^^^^^^^^^^^^^^^^
  File "/home/salohiddin/downlaoderf/instagram-downloader/enhanced_telegram_bot.py", line 54, in start_command
    telegram_user = TelegramUser.objects.filter(telegram_id=user_id).first()
  File "/home/salohiddin/downlaoderf/venv/lib/python3.13/site-packages/django/db/models/query.py", line 1104, in first
    for obj in queryset[:1]:
               ~~~~~~~~^^^^
  File "/home/salohiddin/downlaoderf/venv/lib/python3.13/site-packages/django/db/models/query.py", line 384, in __iter__
    self._fetch_all()
    ~~~~~~~~~~~~~~~^^
  File "/home/salohiddin/downlaoderf/venv/lib/python3.13/site-packages/django/db/models/query.py", line 1945, in _fetch_all
    self._result_cache = list(self._iterable_class(self))
                         ~~~~^^^^^^^^^^^^^^^^^^^^^^^^^^^^
  File "/home/salohiddin/downlaoderf/venv/lib/python3.13/site-packages/django/db/models/query.py", line 91, in __iter__
    results = compiler.execute_sql(
        chunked_fetch=self.chunked_fetch, chunk_size=self.chunk_size
    )
  File "/home/salohiddin/downlaoderf/venv/lib/python3.13/site-packages/django/db/models/sql/compiler.py", line 1621, in execute_sql
    cursor = self.connection.cursor()
  File "/home/salohiddin/downlaoderf/venv/lib/python3.13/site-packages/django/utils/asyncio.py", line 24, in inner
    raise SynchronousOnlyOperation(message)
django.core.exceptions.SynchronousOnlyOperation: You cannot call this from an async context - use a thread or sync_to_async.
2025-10-17 11:40:01,355 - httpx - INFO - HTTP Request: POST https://api.telegram.org/bot8276877025:AAFFPx5w397Zris6iSzFCe4cs6yrcwnnx0E/getUpdates "HTTP/1.1 200 OK"
2025-10-17 11:40:01,356 - telegram.ext.Application - ERROR - No error handlers are registered, logging exception.
Traceback (most recent call last):
  File "/home/salohiddin/downlaoderf/venv/lib/python3.13/site-packages/telegram/ext/_application.py", line 1335, in process_update
    await coroutine
  File "/home/salohiddin/downlaoderf/venv/lib/python3.13/site-packages/telegram/ext/_handlers/basehandler.py", line 157, in handle_update
    return await self.callback(update, context)
           ^^^^^^^^^^^^^^^^^^^^^^^^^^^^^^^^^^^^
  File "/home/salohiddin/downlaoderf/instagram-downloader/enhanced_telegram_bot.py", line 54, in start_command
    telegram_user = TelegramUser.objects.filter(telegram_id=user_id).first()
  File "/home/salohiddin/downlaoderf/venv/lib/python3.13/site-packages/django/db/models/query.py", line 1104, in first
    for obj in queryset[:1]:
               ~~~~~~~~^^^^
  File "/home/salohiddin/downlaoderf/venv/lib/python3.13/site-packages/django/db/models/query.py", line 384, in __iter__
    self._fetch_all()
    ~~~~~~~~~~~~~~~^^
  File "/home/salohiddin/downlaoderf/venv/lib/python3.13/site-packages/django/db/models/query.py", line 1945, in _fetch_all
    self._result_cache = list(self._iterable_class(self))
                         ~~~~^^^^^^^^^^^^^^^^^^^^^^^^^^^^
  File "/home/salohiddin/downlaoderf/venv/lib/python3.13/site-packages/django/db/models/query.py", line 91, in __iter__
    results = compiler.execute_sql(
        chunked_fetch=self.chunked_fetch, chunk_size=self.chunk_size
    )
  File "/home/salohiddin/downlaoderf/venv/lib/python3.13/site-packages/django/db/models/sql/compiler.py", line 1621, in execute_sql
    cursor = self.connection.cursor()
  File "/home/salohiddin/downlaoderf/venv/lib/python3.13/site-packages/django/utils/asyncio.py", line 24, in inner
    raise SynchronousOnlyOperation(message)
django.core.exceptions.SynchronousOnlyOperation: You cannot call this from an async context - use a thread or sync_to_async.
2025-10-17 11:40:11,540 - httpx - INFO - HTTP Request: POST https://api.telegram.org/bot8276877025:AAFFPx5w397Zris6iSzFCe4cs6yrcwnnx0E/getUpdates "HTTP/1.1 200 OK"
2025-10-17 11:40:21,680 - httpx - INFO - HTTP Request: POST https://api.telegram.org/bot8276877025:AAFFPx5w397Zris6iSzFCe4cs6yrcwnnx0E/getUpdates "HTTP/1.1 200 OK"
2025-10-17 11:40:31,817 - httpx - INFO - HTTP Request: POST https://api.telegram.org/bot8276877025:AAFFPx5w397Zris6iSzFCe4cs6yrcwnnx0E/getUpdates "HTTP/1.1 200 OK"
2025-10-17 11:40:41,928 - httpx - INFO - HTTP Request: POST https://api.telegram.org/bot8276877025:AAFFPx5w397Zris6iSzFCe4cs6yrcwnnx0E/getUpdates "HTTP/1.1 200 OK"
2025-10-17 11:40:52,091 - httpx - INFO - HTTP Request: POST https://api.telegram.org/bot8276877025:AAFFPx5w397Zris6iSzFCe4cs6yrcwnnx0E/getUpdates "HTTP/1.1 200 OK"
2025-10-17 11:41:02,227 - httpx - INFO - HTTP Request: POST https://api.telegram.org/bot8276877025:AAFFPx5w397Zris6iSzFCe4cs6yrcwnnx0E/getUpdates "HTTP/1.1 200 OK"
2025-10-17 11:41:12,366 - httpx - INFO - HTTP Request: POST https://api.telegram.org/bot8276877025:AAFFPx5w397Zris6iSzFCe4cs6yrcwnnx0E/getUpdates "HTTP/1.1 200 OK"
2025-10-17 11:41:22,469 - httpx - INFO - HTTP Request: POST https://api.telegram.org/bot8276877025:AAFFPx5w397Zris6iSzFCe4cs6yrcwnnx0E/getUpdates "HTTP/1.1 200 OK"
2025-10-17 11:41:32,946 - httpx - INFO - HTTP Request: POST https://api.telegram.org/bot8276877025:AAFFPx5w397Zris6iSzFCe4cs6yrcwnnx0E/getUpdates "HTTP/1.1 200 OK"
2025-10-17 11:41:43,087 - httpx - INFO - HTTP Request: POST https://api.telegram.org/bot8276877025:AAFFPx5w397Zris6iSzFCe4cs6yrcwnnx0E/getUpdates "HTTP/1.1 200 OK"
2025-10-17 11:41:49,737 - httpx - INFO - HTTP Request: POST https://api.telegram.org/bot8276877025:AAFFPx5w397Zris6iSzFCe4cs6yrcwnnx0E/getUpdates "HTTP/1.1 200 OK"
2025-10-17 11:41:49,738 - telegram.ext.Application - ERROR - No error handlers are registered, logging exception.
Traceback (most recent call last):
  File "/home/salohiddin/downlaoderf/venv/lib/python3.13/site-packages/telegram/ext/_application.py", line 1335, in process_update
    await coroutine
  File "/home/salohiddin/downlaoderf/venv/lib/python3.13/site-packages/telegram/ext/_handlers/basehandler.py", line 157, in handle_update
    return await self.callback(update, context)
           ^^^^^^^^^^^^^^^^^^^^^^^^^^^^^^^^^^^^
  File "/home/salohiddin/downlaoderf/instagram-downloader/enhanced_telegram_bot.py", line 54, in start_command
    telegram_user = TelegramUser.objects.filter(telegram_id=user_id).first()
  File "/home/salohiddin/downlaoderf/venv/lib/python3.13/site-packages/django/db/models/query.py", line 1104, in first
    for obj in queryset[:1]:
               ~~~~~~~~^^^^
  File "/home/salohiddin/downlaoderf/venv/lib/python3.13/site-packages/django/db/models/query.py", line 384, in __iter__
    self._fetch_all()
    ~~~~~~~~~~~~~~~^^
  File "/home/salohiddin/downlaoderf/venv/lib/python3.13/site-packages/django/db/models/query.py", line 1945, in _fetch_all
    self._result_cache = list(self._iterable_class(self))
                         ~~~~^^^^^^^^^^^^^^^^^^^^^^^^^^^^
  File "/home/salohiddin/downlaoderf/venv/lib/python3.13/site-packages/django/db/models/query.py", line 91, in __iter__
    results = compiler.execute_sql(
        chunked_fetch=self.chunked_fetch, chunk_size=self.chunk_size
    )
  File "/home/salohiddin/downlaoderf/venv/lib/python3.13/site-packages/django/db/models/sql/compiler.py", line 1621, in execute_sql
    cursor = self.connection.cursor()
  File "/home/salohiddin/downlaoderf/venv/lib/python3.13/site-packages/django/utils/asyncio.py", line 24, in inner
    raise SynchronousOnlyOperation(message)
django.core.exceptions.SynchronousOnlyOperation: You cannot call this from an async context - use a thread or sync_to_async.
2025-10-17 11:41:50,329 - httpx - INFO - HTTP Request: POST https://api.telegram.org/bot8276877025:AAFFPx5w397Zris6iSzFCe4cs6yrcwnnx0E/getUpdates "HTTP/1.1 200 OK"
2025-10-17 11:41:50,332 - telegram.ext.Application - ERROR - No error handlers are registered, logging exception.
Traceback (most recent call last):
  File "/home/salohiddin/downlaoderf/venv/lib/python3.13/site-packages/telegram/ext/_application.py", line 1335, in process_update
    await coroutine
  File "/home/salohiddin/downlaoderf/venv/lib/python3.13/site-packages/telegram/ext/_handlers/basehandler.py", line 157, in handle_update
    return await self.callback(update, context)
           ^^^^^^^^^^^^^^^^^^^^^^^^^^^^^^^^^^^^
  File "/home/salohiddin/downlaoderf/instagram-downloader/enhanced_telegram_bot.py", line 54, in start_command
    telegram_user = TelegramUser.objects.filter(telegram_id=user_id).first()
  File "/home/salohiddin/downlaoderf/venv/lib/python3.13/site-packages/django/db/models/query.py", line 1104, in first
    for obj in queryset[:1]:
               ~~~~~~~~^^^^
  File "/home/salohiddin/downlaoderf/venv/lib/python3.13/site-packages/django/db/models/query.py", line 384, in __iter__
    self._fetch_all()
    ~~~~~~~~~~~~~~~^^
  File "/home/salohiddin/downlaoderf/venv/lib/python3.13/site-packages/django/db/models/query.py", line 1945, in _fetch_all
    self._result_cache = list(self._iterable_class(self))
                         ~~~~^^^^^^^^^^^^^^^^^^^^^^^^^^^^
  File "/home/salohiddin/downlaoderf/venv/lib/python3.13/site-packages/django/db/models/query.py", line 91, in __iter__
    results = compiler.execute_sql(
        chunked_fetch=self.chunked_fetch, chunk_size=self.chunk_size
    )
  File "/home/salohiddin/downlaoderf/venv/lib/python3.13/site-packages/django/db/models/sql/compiler.py", line 1621, in execute_sql
    cursor = self.connection.cursor()
  File "/home/salohiddin/downlaoderf/venv/lib/python3.13/site-packages/django/utils/asyncio.py", line 24, in inner
    raise SynchronousOnlyOperation(message)
django.core.exceptions.SynchronousOnlyOperation: You cannot call this from an async context - use a thread or sync_to_async.
2025-10-17 11:41:50,670 - httpx - INFO - HTTP Request: POST https://api.telegram.org/bot8276877025:AAFFPx5w397Zris6iSzFCe4cs6yrcwnnx0E/getUpdates "HTTP/1.1 200 OK"
2025-10-17 11:41:50,671 - telegram.ext.Application - ERROR - No error handlers are registered, logging exception.
Traceback (most recent call last):
  File "/home/salohiddin/downlaoderf/venv/lib/python3.13/site-packages/telegram/ext/_application.py", line 1335, in process_update
    await coroutine
  File "/home/salohiddin/downlaoderf/venv/lib/python3.13/site-packages/telegram/ext/_handlers/basehandler.py", line 157, in handle_update
    return await self.callback(update, context)
           ^^^^^^^^^^^^^^^^^^^^^^^^^^^^^^^^^^^^
  File "/home/salohiddin/downlaoderf/instagram-downloader/enhanced_telegram_bot.py", line 54, in start_command
    telegram_user = TelegramUser.objects.filter(telegram_id=user_id).first()
  File "/home/salohiddin/downlaoderf/venv/lib/python3.13/site-packages/django/db/models/query.py", line 1104, in first
    for obj in queryset[:1]:
               ~~~~~~~~^^^^
  File "/home/salohiddin/downlaoderf/venv/lib/python3.13/site-packages/django/db/models/query.py", line 384, in __iter__
    self._fetch_all()
    ~~~~~~~~~~~~~~~^^
  File "/home/salohiddin/downlaoderf/venv/lib/python3.13/site-packages/django/db/models/query.py", line 1945, in _fetch_all
    self._result_cache = list(self._iterable_class(self))
                         ~~~~^^^^^^^^^^^^^^^^^^^^^^^^^^^^
  File "/home/salohiddin/downlaoderf/venv/lib/python3.13/site-packages/django/db/models/query.py", line 91, in __iter__
    results = compiler.execute_sql(
        chunked_fetch=self.chunked_fetch, chunk_size=self.chunk_size
    )
  File "/home/salohiddin/downlaoderf/venv/lib/python3.13/site-packages/django/db/models/sql/compiler.py", line 1621, in execute_sql
    cursor = self.connection.cursor()
  File "/home/salohiddin/downlaoderf/venv/lib/python3.13/site-packages/django/utils/asyncio.py", line 24, in inner
    raise SynchronousOnlyOperation(message)
django.core.exceptions.SynchronousOnlyOperation: You cannot call this from an async context - use a thread or sync_to_async.
2025-10-17 11:41:52,024 - httpx - INFO - HTTP Request: POST https://api.telegram.org/bot8276877025:AAFFPx5w397Zris6iSzFCe4cs6yrcwnnx0E/getUpdates "HTTP/1.1 409 Conflict"
2025-10-17 11:41:52,024 - telegram.ext.Application - ERROR - No error handlers are registered, logging exception.
Traceback (most recent call last):
  File "/home/salohiddin/downlaoderf/venv/lib/python3.13/site-packages/telegram/ext/_updater.py", line 753, in _network_loop_retry
    if not await do_action():
           ^^^^^^^^^^^^^^^^^
  File "/home/salohiddin/downlaoderf/venv/lib/python3.13/site-packages/telegram/ext/_updater.py", line 747, in do_action
    return action_cb_task.result()
           ~~~~~~~~~~~~~~~~~~~~~^^
  File "/home/salohiddin/downlaoderf/venv/lib/python3.13/site-packages/telegram/ext/_updater.py", line 377, in polling_action_cb
    updates = await self.bot.get_updates(
              ^^^^^^^^^^^^^^^^^^^^^^^^^^^
    ...<7 lines>...
    )
    ^
  File "/home/salohiddin/downlaoderf/venv/lib/python3.13/site-packages/telegram/ext/_extbot.py", line 649, in get_updates
    updates = await super().get_updates(
              ^^^^^^^^^^^^^^^^^^^^^^^^^^
    ...<9 lines>...
    )
    ^
  File "/home/salohiddin/downlaoderf/venv/lib/python3.13/site-packages/telegram/_bot.py", line 4366, in get_updates
    await self._post(
    ^^^^^^^^^^^^^^^^^
    ...<7 lines>...
    ),
    ^
  File "/home/salohiddin/downlaoderf/venv/lib/python3.13/site-packages/telegram/_bot.py", line 623, in _post
    return await self._do_post(
           ^^^^^^^^^^^^^^^^^^^^
    ...<6 lines>...
    )
    ^
  File "/home/salohiddin/downlaoderf/venv/lib/python3.13/site-packages/telegram/ext/_extbot.py", line 355, in _do_post
    return await super()._do_post(
           ^^^^^^^^^^^^^^^^^^^^^^^
    ...<6 lines>...
    )
    ^
  File "/home/salohiddin/downlaoderf/venv/lib/python3.13/site-packages/telegram/_bot.py", line 652, in _do_post
    result = await request.post(
             ^^^^^^^^^^^^^^^^^^^
    ...<6 lines>...
    )
    ^
  File "/home/salohiddin/downlaoderf/venv/lib/python3.13/site-packages/telegram/request/_baserequest.py", line 201, in post
    result = await self._request_wrapper(
             ^^^^^^^^^^^^^^^^^^^^^^^^^^^^
    ...<7 lines>...
    )
    ^
  File "/home/salohiddin/downlaoderf/venv/lib/python3.13/site-packages/telegram/request/_baserequest.py", line 384, in _request_wrapper
    raise Conflict(message)
telegram.error.Conflict: Conflict: terminated by other getUpdates request; make sure that only one bot instance is running
2025-10-17 11:41:57,325 - httpx - INFO - HTTP Request: POST https://api.telegram.org/bot8276877025:AAFFPx5w397Zris6iSzFCe4cs6yrcwnnx0E/getUpdates "HTTP/1.1 409 Conflict"
2025-10-17 11:41:57,325 - telegram.ext.Application - ERROR - No error handlers are registered, logging exception.
Traceback (most recent call last):
  File "/home/salohiddin/downlaoderf/venv/lib/python3.13/site-packages/telegram/ext/_updater.py", line 753, in _network_loop_retry
    if not await do_action():
           ^^^^^^^^^^^^^^^^^
  File "/home/salohiddin/downlaoderf/venv/lib/python3.13/site-packages/telegram/ext/_updater.py", line 747, in do_action
    return action_cb_task.result()
           ~~~~~~~~~~~~~~~~~~~~~^^
  File "/home/salohiddin/downlaoderf/venv/lib/python3.13/site-packages/telegram/ext/_updater.py", line 377, in polling_action_cb
    updates = await self.bot.get_updates(
              ^^^^^^^^^^^^^^^^^^^^^^^^^^^
    ...<7 lines>...
    )
    ^
  File "/home/salohiddin/downlaoderf/venv/lib/python3.13/site-packages/telegram/ext/_extbot.py", line 649, in get_updates
    updates = await super().get_updates(
              ^^^^^^^^^^^^^^^^^^^^^^^^^^
    ...<9 lines>...
    )
    ^
  File "/home/salohiddin/downlaoderf/venv/lib/python3.13/site-packages/telegram/_bot.py", line 4366, in get_updates
    await self._post(
    ^^^^^^^^^^^^^^^^^
    ...<7 lines>...
    ),
    ^
  File "/home/salohiddin/downlaoderf/venv/lib/python3.13/site-packages/telegram/_bot.py", line 623, in _post
    return await self._do_post(
           ^^^^^^^^^^^^^^^^^^^^
    ...<6 lines>...
    )
    ^
  File "/home/salohiddin/downlaoderf/venv/lib/python3.13/site-packages/telegram/ext/_extbot.py", line 355, in _do_post
    return await super()._do_post(
           ^^^^^^^^^^^^^^^^^^^^^^^
    ...<6 lines>...
    )
    ^
  File "/home/salohiddin/downlaoderf/venv/lib/python3.13/site-packages/telegram/_bot.py", line 652, in _do_post
    result = await request.post(
             ^^^^^^^^^^^^^^^^^^^
    ...<6 lines>...
    )
    ^
  File "/home/salohiddin/downlaoderf/venv/lib/python3.13/site-packages/telegram/request/_baserequest.py", line 201, in post
    result = await self._request_wrapper(
             ^^^^^^^^^^^^^^^^^^^^^^^^^^^^
    ...<7 lines>...
    )
    ^
  File "/home/salohiddin/downlaoderf/venv/lib/python3.13/site-packages/telegram/request/_baserequest.py", line 384, in _request_wrapper
    raise Conflict(message)
telegram.error.Conflict: Conflict: terminated by other getUpdates request; make sure that only one bot instance is running
2025-10-17 11:42:03,668 - httpx - INFO - HTTP Request: POST https://api.telegram.org/bot8276877025:AAFFPx5w397Zris6iSzFCe4cs6yrcwnnx0E/getUpdates "HTTP/1.1 409 Conflict"
2025-10-17 11:42:03,669 - telegram.ext.Application - ERROR - No error handlers are registered, logging exception.
Traceback (most recent call last):
  File "/home/salohiddin/downlaoderf/venv/lib/python3.13/site-packages/telegram/ext/_updater.py", line 753, in _network_loop_retry
    if not await do_action():
           ^^^^^^^^^^^^^^^^^
  File "/home/salohiddin/downlaoderf/venv/lib/python3.13/site-packages/telegram/ext/_updater.py", line 747, in do_action
    return action_cb_task.result()
           ~~~~~~~~~~~~~~~~~~~~~^^
  File "/home/salohiddin/downlaoderf/venv/lib/python3.13/site-packages/telegram/ext/_updater.py", line 377, in polling_action_cb
    updates = await self.bot.get_updates(
              ^^^^^^^^^^^^^^^^^^^^^^^^^^^
    ...<7 lines>...
    )
    ^
  File "/home/salohiddin/downlaoderf/venv/lib/python3.13/site-packages/telegram/ext/_extbot.py", line 649, in get_updates
    updates = await super().get_updates(
              ^^^^^^^^^^^^^^^^^^^^^^^^^^
    ...<9 lines>...
    )
    ^
  File "/home/salohiddin/downlaoderf/venv/lib/python3.13/site-packages/telegram/_bot.py", line 4366, in get_updates
    await self._post(
    ^^^^^^^^^^^^^^^^^
    ...<7 lines>...
    ),
    ^
  File "/home/salohiddin/downlaoderf/venv/lib/python3.13/site-packages/telegram/_bot.py", line 623, in _post
    return await self._do_post(
           ^^^^^^^^^^^^^^^^^^^^
    ...<6 lines>...
    )
    ^
  File "/home/salohiddin/downlaoderf/venv/lib/python3.13/site-packages/telegram/ext/_extbot.py", line 355, in _do_post
    return await super()._do_post(
           ^^^^^^^^^^^^^^^^^^^^^^^
    ...<6 lines>...
    )
    ^
  File "/home/salohiddin/downlaoderf/venv/lib/python3.13/site-packages/telegram/_bot.py", line 652, in _do_post
    result = await request.post(
             ^^^^^^^^^^^^^^^^^^^
    ...<6 lines>...
    )
    ^
  File "/home/salohiddin/downlaoderf/venv/lib/python3.13/site-packages/telegram/request/_baserequest.py", line 201, in post
    result = await self._request_wrapper(
             ^^^^^^^^^^^^^^^^^^^^^^^^^^^^
    ...<7 lines>...
    )
    ^
  File "/home/salohiddin/downlaoderf/venv/lib/python3.13/site-packages/telegram/request/_baserequest.py", line 384, in _request_wrapper
    raise Conflict(message)
telegram.error.Conflict: Conflict: terminated by other getUpdates request; make sure that only one bot instance is running
2025-10-17 11:42:16,023 - httpx - INFO - HTTP Request: POST https://api.telegram.org/bot8276877025:AAFFPx5w397Zris6iSzFCe4cs6yrcwnnx0E/getUpdates "HTTP/1.1 200 OK"
2025-10-17 11:42:26,140 - httpx - INFO - HTTP Request: POST https://api.telegram.org/bot8276877025:AAFFPx5w397Zris6iSzFCe4cs6yrcwnnx0E/getUpdates "HTTP/1.1 200 OK"
2025-10-17 11:42:29,489 - httpx - INFO - HTTP Request: POST https://api.telegram.org/bot8276877025:AAFFPx5w397Zris6iSzFCe4cs6yrcwnnx0E/getUpdates "HTTP/1.1 200 OK"
2025-10-17 11:42:29,490 - telegram.ext.Application - INFO - Application is stopping. This might take a moment.
2025-10-17 11:42:29,490 - telegram.ext.Application - INFO - Application.stop() complete
